[ERROR] [2020-10-29 08:04:43,342] [6:140638279530240] - session_utils.py[line:100]: session session_used_by_fate_flow_server_fe08f93219bc11eba1cc0242ac120002 count error
Traceback (most recent call last):
  File "/fate/fate_flow/utils/session_utils.py", line 96, in _wrapper
    raise Exception("session {} count error".format(session.get_session_id()))
Exception: session session_used_by_fate_flow_server_fe08f93219bc11eba1cc0242ac120002 count error
[ERROR] [2020-10-29 08:04:43,356] [6:140638279530240] - session_utils.py[line:100]: session session_used_by_fate_flow_server_670e4a4019bd11ebadef0242ac120002 count error
Traceback (most recent call last):
  File "/fate/fate_flow/utils/session_utils.py", line 96, in _wrapper
    raise Exception("session {} count error".format(session.get_session_id()))
Exception: session session_used_by_fate_flow_server_670e4a4019bd11ebadef0242ac120002 count error
[ERROR] [2020-10-29 08:04:43,368] [6:140638279530240] - session_utils.py[line:100]: session session_used_by_fate_flow_server_6710752219bd11ebadef0242ac120002 count error
Traceback (most recent call last):
  File "/fate/fate_flow/utils/session_utils.py", line 96, in _wrapper
    raise Exception("session {} count error".format(session.get_session_id()))
Exception: session session_used_by_fate_flow_server_6710752219bd11ebadef0242ac120002 count error
[ERROR] [2020-10-29 08:04:43,379] [6:140638279530240] - session_utils.py[line:109]: init new session failed.
[ERROR] [2020-10-29 08:04:43,459] [6:140638279530240] - session_utils.py[line:100]: session session_used_by_fate_flow_server_67124bcc19bd11ebadef0242ac120002 count error
Traceback (most recent call last):
  File "/fate/fate_flow/utils/session_utils.py", line 96, in _wrapper
    raise Exception("session {} count error".format(session.get_session_id()))
Exception: session session_used_by_fate_flow_server_67124bcc19bd11ebadef0242ac120002 count error
[ERROR] [2020-10-29 08:04:43,499] [6:140638279530240] - session_utils.py[line:100]: session session_used_by_fate_flow_server_6721121a19bd11eb89b90242ac120002 count error
Traceback (most recent call last):
  File "/fate/fate_flow/utils/session_utils.py", line 96, in _wrapper
    raise Exception("session {} count error".format(session.get_session_id()))
Exception: session session_used_by_fate_flow_server_6721121a19bd11eb89b90242ac120002 count error
[ERROR] [2020-10-29 08:04:43,512] [6:140638279530240] - session_utils.py[line:100]: session session_used_by_fate_flow_server_67263d2619bd11eb89b90242ac120002 count error
Traceback (most recent call last):
  File "/fate/fate_flow/utils/session_utils.py", line 96, in _wrapper
    raise Exception("session {} count error".format(session.get_session_id()))
Exception: session session_used_by_fate_flow_server_67263d2619bd11eb89b90242ac120002 count error
[ERROR] [2020-10-29 08:04:43,523] [6:140638279530240] - session_utils.py[line:109]: init new session failed.
[ERROR] [2020-10-29 08:04:44,743] [6:140702878570240] - session_utils.py[line:100]: session session_used_by_fate_flow_server_6728412a19bd11eb89b90242ac120002 count error
Traceback (most recent call last):
  File "/fate/fate_flow/utils/session_utils.py", line 96, in _wrapper
    raise Exception("session {} count error".format(session.get_session_id()))
Exception: session session_used_by_fate_flow_server_6728412a19bd11eb89b90242ac120002 count error
[ERROR] [2020-10-29 08:04:44,759] [6:140702878570240] - session_utils.py[line:100]: session session_used_by_fate_flow_server_67e4262419bd11eba8be0242ac120002 count error
Traceback (most recent call last):
  File "/fate/fate_flow/utils/session_utils.py", line 96, in _wrapper
    raise Exception("session {} count error".format(session.get_session_id()))
Exception: session session_used_by_fate_flow_server_67e4262419bd11eba8be0242ac120002 count error
[ERROR] [2020-10-29 08:04:44,776] [6:140702878570240] - session_utils.py[line:100]: session session_used_by_fate_flow_server_67e68e0019bd11eba8be0242ac120002 count error
Traceback (most recent call last):
  File "/fate/fate_flow/utils/session_utils.py", line 96, in _wrapper
    raise Exception("session {} count error".format(session.get_session_id()))
Exception: session session_used_by_fate_flow_server_67e68e0019bd11eba8be0242ac120002 count error
[ERROR] [2020-10-29 08:04:44,789] [6:140702878570240] - session_utils.py[line:109]: init new session failed.
[ERROR] [2020-10-29 08:04:45,094] [6:140638279530240] - session_utils.py[line:100]: session session_used_by_fate_flow_server_67e91c5619bd11eba8be0242ac120002 count error
Traceback (most recent call last):
  File "/fate/fate_flow/utils/session_utils.py", line 96, in _wrapper
    raise Exception("session {} count error".format(session.get_session_id()))
Exception: session session_used_by_fate_flow_server_67e91c5619bd11eba8be0242ac120002 count error
[ERROR] [2020-10-29 08:04:45,109] [6:140638279530240] - session_utils.py[line:100]: session session_used_by_fate_flow_server_681998fe19bd11ebbe3a0242ac120002 count error
Traceback (most recent call last):
  File "/fate/fate_flow/utils/session_utils.py", line 96, in _wrapper
    raise Exception("session {} count error".format(session.get_session_id()))
Exception: session session_used_by_fate_flow_server_681998fe19bd11ebbe3a0242ac120002 count error
[ERROR] [2020-10-29 08:04:45,123] [6:140638279530240] - session_utils.py[line:100]: session session_used_by_fate_flow_server_681c018e19bd11ebbe3a0242ac120002 count error
Traceback (most recent call last):
  File "/fate/fate_flow/utils/session_utils.py", line 96, in _wrapper
    raise Exception("session {} count error".format(session.get_session_id()))
Exception: session session_used_by_fate_flow_server_681c018e19bd11ebbe3a0242ac120002 count error
[ERROR] [2020-10-29 08:04:45,132] [6:140638279530240] - session_utils.py[line:109]: init new session failed.
[ERROR] [2020-10-29 08:04:45,624] [6:140637848127232] - session_utils.py[line:100]: session session_used_by_fate_flow_server_681dfdae19bd11ebbe3a0242ac120002 count error
Traceback (most recent call last):
  File "/fate/fate_flow/utils/session_utils.py", line 96, in _wrapper
    raise Exception("session {} count error".format(session.get_session_id()))
Exception: session session_used_by_fate_flow_server_681dfdae19bd11ebbe3a0242ac120002 count error
[ERROR] [2020-10-29 08:04:45,637] [6:140637848127232] - session_utils.py[line:100]: session session_used_by_fate_flow_server_686a846c19bd11eba0880242ac120002 count error
Traceback (most recent call last):
  File "/fate/fate_flow/utils/session_utils.py", line 96, in _wrapper
    raise Exception("session {} count error".format(session.get_session_id()))
Exception: session session_used_by_fate_flow_server_686a846c19bd11eba0880242ac120002 count error
[ERROR] [2020-10-29 08:04:45,648] [6:140637848127232] - session_utils.py[line:100]: session session_used_by_fate_flow_server_686c7b3c19bd11eba0880242ac120002 count error
Traceback (most recent call last):
  File "/fate/fate_flow/utils/session_utils.py", line 96, in _wrapper
    raise Exception("session {} count error".format(session.get_session_id()))
Exception: session session_used_by_fate_flow_server_686c7b3c19bd11eba0880242ac120002 count error
[ERROR] [2020-10-29 08:04:45,660] [6:140637848127232] - session_utils.py[line:109]: init new session failed.
[ERROR] [2020-10-29 08:04:45,673] [6:140637848127232] - session_utils.py[line:100]: session session_used_by_fate_flow_server_686e2e0a19bd11eba0880242ac120002 count error
Traceback (most recent call last):
  File "/fate/fate_flow/utils/session_utils.py", line 96, in _wrapper
    raise Exception("session {} count error".format(session.get_session_id()))
Exception: session session_used_by_fate_flow_server_686e2e0a19bd11eba0880242ac120002 count error
[ERROR] [2020-10-29 08:04:45,686] [6:140637848127232] - session_utils.py[line:100]: session session_used_by_fate_flow_server_6871fdfa19bd11eba03b0242ac120002 count error
Traceback (most recent call last):
  File "/fate/fate_flow/utils/session_utils.py", line 96, in _wrapper
    raise Exception("session {} count error".format(session.get_session_id()))
Exception: session session_used_by_fate_flow_server_6871fdfa19bd11eba03b0242ac120002 count error
[ERROR] [2020-10-29 08:04:45,700] [6:140637848127232] - session_utils.py[line:100]: session session_used_by_fate_flow_server_6873fac419bd11eba03b0242ac120002 count error
Traceback (most recent call last):
  File "/fate/fate_flow/utils/session_utils.py", line 96, in _wrapper
    raise Exception("session {} count error".format(session.get_session_id()))
Exception: session session_used_by_fate_flow_server_6873fac419bd11eba03b0242ac120002 count error
[ERROR] [2020-10-29 08:04:45,711] [6:140637848127232] - session_utils.py[line:109]: init new session failed.
[ERROR] [2020-10-29 08:04:46,910] [6:140702878570240] - session_utils.py[line:100]: session session_used_by_fate_flow_server_68761a3e19bd11eba03b0242ac120002 count error
Traceback (most recent call last):
  File "/fate/fate_flow/utils/session_utils.py", line 96, in _wrapper
    raise Exception("session {} count error".format(session.get_session_id()))
Exception: session session_used_by_fate_flow_server_68761a3e19bd11eba03b0242ac120002 count error
[ERROR] [2020-10-29 08:04:46,925] [6:140702878570240] - session_utils.py[line:100]: session session_used_by_fate_flow_server_692ecdc219bd11ebb5a00242ac120002 count error
Traceback (most recent call last):
  File "/fate/fate_flow/utils/session_utils.py", line 96, in _wrapper
    raise Exception("session {} count error".format(session.get_session_id()))
Exception: session session_used_by_fate_flow_server_692ecdc219bd11ebb5a00242ac120002 count error
[ERROR] [2020-10-29 08:04:46,938] [6:140702878570240] - session_utils.py[line:100]: session session_used_by_fate_flow_server_6930f5d419bd11ebb5a00242ac120002 count error
Traceback (most recent call last):
  File "/fate/fate_flow/utils/session_utils.py", line 96, in _wrapper
    raise Exception("session {} count error".format(session.get_session_id()))
Exception: session session_used_by_fate_flow_server_6930f5d419bd11ebb5a00242ac120002 count error
[ERROR] [2020-10-29 08:04:46,950] [6:140702878570240] - session_utils.py[line:109]: init new session failed.
[ERROR] [2020-10-29 08:04:51,093] [6:140540940003072] - session_utils.py[line:100]: session session_used_by_fate_flow_server_693314ae19bd11ebb5a00242ac120002 count error
Traceback (most recent call last):
  File "/fate/fate_flow/utils/session_utils.py", line 96, in _wrapper
    raise Exception("session {} count error".format(session.get_session_id()))
Exception: session session_used_by_fate_flow_server_693314ae19bd11ebb5a00242ac120002 count error
[ERROR] [2020-10-29 08:04:51,107] [6:140540940003072] - session_utils.py[line:100]: session session_used_by_fate_flow_server_6bad19a019bd11ebb7910242ac120002 count error
Traceback (most recent call last):
  File "/fate/fate_flow/utils/session_utils.py", line 96, in _wrapper
    raise Exception("session {} count error".format(session.get_session_id()))
Exception: session session_used_by_fate_flow_server_6bad19a019bd11ebb7910242ac120002 count error
[ERROR] [2020-10-29 08:04:51,120] [6:140540940003072] - session_utils.py[line:100]: session session_used_by_fate_flow_server_6baf36d619bd11ebb7910242ac120002 count error
Traceback (most recent call last):
  File "/fate/fate_flow/utils/session_utils.py", line 96, in _wrapper
    raise Exception("session {} count error".format(session.get_session_id()))
Exception: session session_used_by_fate_flow_server_6baf36d619bd11ebb7910242ac120002 count error
[ERROR] [2020-10-29 08:04:51,131] [6:140540940003072] - session_utils.py[line:109]: init new session failed.
[ERROR] [2020-10-29 08:04:51,148] [6:140540940003072] - session_utils.py[line:100]: session session_used_by_fate_flow_server_6bb1342c19bd11ebb7910242ac120002 count error
Traceback (most recent call last):
  File "/fate/fate_flow/utils/session_utils.py", line 96, in _wrapper
    raise Exception("session {} count error".format(session.get_session_id()))
Exception: session session_used_by_fate_flow_server_6bb1342c19bd11ebb7910242ac120002 count error
[ERROR] [2020-10-29 08:04:51,164] [6:140540940003072] - session_utils.py[line:100]: session session_used_by_fate_flow_server_6bb5907619bd11ebb17a0242ac120002 count error
Traceback (most recent call last):
  File "/fate/fate_flow/utils/session_utils.py", line 96, in _wrapper
    raise Exception("session {} count error".format(session.get_session_id()))
Exception: session session_used_by_fate_flow_server_6bb5907619bd11ebb17a0242ac120002 count error
[ERROR] [2020-10-29 08:04:51,178] [6:140540940003072] - session_utils.py[line:100]: session session_used_by_fate_flow_server_6bb7e1fa19bd11ebb17a0242ac120002 count error
Traceback (most recent call last):
  File "/fate/fate_flow/utils/session_utils.py", line 96, in _wrapper
    raise Exception("session {} count error".format(session.get_session_id()))
Exception: session session_used_by_fate_flow_server_6bb7e1fa19bd11ebb17a0242ac120002 count error
[ERROR] [2020-10-29 08:04:51,189] [6:140540940003072] - session_utils.py[line:109]: init new session failed.
[ERROR] [2020-10-29 08:05:00,073] [6:140540940003072] - session_utils.py[line:100]: session session_used_by_fate_flow_server_6bb9f2ce19bd11ebb17a0242ac120002 count error
Traceback (most recent call last):
  File "/fate/fate_flow/utils/session_utils.py", line 96, in _wrapper
    raise Exception("session {} count error".format(session.get_session_id()))
Exception: session session_used_by_fate_flow_server_6bb9f2ce19bd11ebb17a0242ac120002 count error
[ERROR] [2020-10-29 08:05:00,089] [6:140540940003072] - session_utils.py[line:100]: session session_used_by_fate_flow_server_7107526219bd11eba0910242ac120002 count error
Traceback (most recent call last):
  File "/fate/fate_flow/utils/session_utils.py", line 96, in _wrapper
    raise Exception("session {} count error".format(session.get_session_id()))
Exception: session session_used_by_fate_flow_server_7107526219bd11eba0910242ac120002 count error
[ERROR] [2020-10-29 08:05:00,105] [6:140540940003072] - session_utils.py[line:100]: session session_used_by_fate_flow_server_7109c98419bd11eba0910242ac120002 count error
Traceback (most recent call last):
  File "/fate/fate_flow/utils/session_utils.py", line 96, in _wrapper
    raise Exception("session {} count error".format(session.get_session_id()))
Exception: session session_used_by_fate_flow_server_7109c98419bd11eba0910242ac120002 count error
[ERROR] [2020-10-29 08:05:00,117] [6:140540940003072] - session_utils.py[line:109]: init new session failed.
[ERROR] [2020-10-29 08:05:00,124] [6:140540940003072] - session_utils.py[line:100]: session session_used_by_fate_flow_server_710c35d419bd11eba0910242ac120002 count error
Traceback (most recent call last):
  File "/fate/fate_flow/utils/session_utils.py", line 96, in _wrapper
    raise Exception("session {} count error".format(session.get_session_id()))
Exception: session session_used_by_fate_flow_server_710c35d419bd11eba0910242ac120002 count error
[ERROR] [2020-10-29 08:05:00,140] [6:140540940003072] - session_utils.py[line:100]: session session_used_by_fate_flow_server_710f1df819bd11eba0910242ac120002 count error
Traceback (most recent call last):
  File "/fate/fate_flow/utils/session_utils.py", line 96, in _wrapper
    raise Exception("session {} count error".format(session.get_session_id()))
Exception: session session_used_by_fate_flow_server_710f1df819bd11eba0910242ac120002 count error
[ERROR] [2020-10-29 08:05:00,154] [6:140540940003072] - session_utils.py[line:100]: session session_used_by_fate_flow_server_7111802a19bd11eba0910242ac120002 count error
Traceback (most recent call last):
  File "/fate/fate_flow/utils/session_utils.py", line 96, in _wrapper
    raise Exception("session {} count error".format(session.get_session_id()))
Exception: session session_used_by_fate_flow_server_7111802a19bd11eba0910242ac120002 count error
[ERROR] [2020-10-29 08:05:00,179] [6:140540940003072] - session_utils.py[line:109]: init new session failed.
[ERROR] [2020-10-29 08:05:00,272] [6:140702836623104] - session_utils.py[line:100]: session session_used_by_fate_flow_server_7113ca5619bd11eba0910242ac120002 count error
Traceback (most recent call last):
  File "/fate/fate_flow/utils/session_utils.py", line 96, in _wrapper
    raise Exception("session {} count error".format(session.get_session_id()))
Exception: session session_used_by_fate_flow_server_7113ca5619bd11eba0910242ac120002 count error
[ERROR] [2020-10-29 08:05:00,285] [6:140702836623104] - session_utils.py[line:100]: session session_used_by_fate_flow_server_7125916e19bd11ebaf760242ac120002 count error
Traceback (most recent call last):
  File "/fate/fate_flow/utils/session_utils.py", line 96, in _wrapper
    raise Exception("session {} count error".format(session.get_session_id()))
Exception: session session_used_by_fate_flow_server_7125916e19bd11ebaf760242ac120002 count error
[ERROR] [2020-10-29 08:05:00,315] [6:140702836623104] - session_utils.py[line:100]: session session_used_by_fate_flow_server_71279ce819bd11ebaf760242ac120002 count error
Traceback (most recent call last):
  File "/fate/fate_flow/utils/session_utils.py", line 96, in _wrapper
    raise Exception("session {} count error".format(session.get_session_id()))
Exception: session session_used_by_fate_flow_server_71279ce819bd11ebaf760242ac120002 count error
[ERROR] [2020-10-29 08:05:00,336] [6:140702836623104] - session_utils.py[line:109]: init new session failed.
[ERROR] [2020-10-29 08:05:00,343] [6:140702836623104] - session_utils.py[line:100]: session session_used_by_fate_flow_server_712c3b0e19bd11ebaf760242ac120002 count error
Traceback (most recent call last):
  File "/fate/fate_flow/utils/session_utils.py", line 96, in _wrapper
    raise Exception("session {} count error".format(session.get_session_id()))
Exception: session session_used_by_fate_flow_server_712c3b0e19bd11ebaf760242ac120002 count error
[ERROR] [2020-10-29 08:05:00,396] [6:140702836623104] - session_utils.py[line:100]: session session_used_by_fate_flow_server_7131a92c19bd11ebaf760242ac120002 count error
Traceback (most recent call last):
  File "/fate/fate_flow/utils/session_utils.py", line 96, in _wrapper
    raise Exception("session {} count error".format(session.get_session_id()))
Exception: session session_used_by_fate_flow_server_7131a92c19bd11ebaf760242ac120002 count error
[ERROR] [2020-10-29 08:05:00,414] [6:140702836623104] - session_utils.py[line:100]: session session_used_by_fate_flow_server_713888dc19bd11ebaf760242ac120002 count error
Traceback (most recent call last):
  File "/fate/fate_flow/utils/session_utils.py", line 96, in _wrapper
    raise Exception("session {} count error".format(session.get_session_id()))
Exception: session session_used_by_fate_flow_server_713888dc19bd11ebaf760242ac120002 count error
[ERROR] [2020-10-29 08:05:00,427] [6:140702836623104] - session_utils.py[line:109]: init new session failed.
[ERROR] [2020-10-29 08:05:09,221] [6:140637848127232] - session_utils.py[line:100]: session session_used_by_fate_flow_server_713b699e19bd11ebaf760242ac120002 count error
Traceback (most recent call last):
  File "/fate/fate_flow/utils/session_utils.py", line 96, in _wrapper
    raise Exception("session {} count error".format(session.get_session_id()))
Exception: session session_used_by_fate_flow_server_713b699e19bd11ebaf760242ac120002 count error
[ERROR] [2020-10-29 08:05:09,235] [6:140637848127232] - session_utils.py[line:100]: session session_used_by_fate_flow_server_767b177419bd11eb9f610242ac120002 count error
Traceback (most recent call last):
  File "/fate/fate_flow/utils/session_utils.py", line 96, in _wrapper
    raise Exception("session {} count error".format(session.get_session_id()))
Exception: session session_used_by_fate_flow_server_767b177419bd11eb9f610242ac120002 count error
[ERROR] [2020-10-29 08:05:09,249] [6:140637848127232] - session_utils.py[line:100]: session session_used_by_fate_flow_server_767d4ac619bd11eb9f610242ac120002 count error
Traceback (most recent call last):
  File "/fate/fate_flow/utils/session_utils.py", line 96, in _wrapper
    raise Exception("session {} count error".format(session.get_session_id()))
Exception: session session_used_by_fate_flow_server_767d4ac619bd11eb9f610242ac120002 count error
[ERROR] [2020-10-29 08:05:09,259] [6:140637848127232] - session_utils.py[line:109]: init new session failed.
[ERROR] [2020-10-29 08:05:09,278] [6:140637848127232] - session_utils.py[line:100]: session session_used_by_fate_flow_server_767f6db019bd11eb9f610242ac120002 count error
Traceback (most recent call last):
  File "/fate/fate_flow/utils/session_utils.py", line 96, in _wrapper
    raise Exception("session {} count error".format(session.get_session_id()))
Exception: session session_used_by_fate_flow_server_767f6db019bd11eb9f610242ac120002 count error
[ERROR] [2020-10-29 08:05:09,293] [6:140637848127232] - session_utils.py[line:100]: session session_used_by_fate_flow_server_7683e23219bd11eb9f610242ac120002 count error
Traceback (most recent call last):
  File "/fate/fate_flow/utils/session_utils.py", line 96, in _wrapper
    raise Exception("session {} count error".format(session.get_session_id()))
Exception: session session_used_by_fate_flow_server_7683e23219bd11eb9f610242ac120002 count error
[ERROR] [2020-10-29 08:05:09,308] [6:140637848127232] - session_utils.py[line:100]: session session_used_by_fate_flow_server_7686321c19bd11eb9f610242ac120002 count error
Traceback (most recent call last):
  File "/fate/fate_flow/utils/session_utils.py", line 96, in _wrapper
    raise Exception("session {} count error".format(session.get_session_id()))
Exception: session session_used_by_fate_flow_server_7686321c19bd11eb9f610242ac120002 count error
[ERROR] [2020-10-29 08:05:09,319] [6:140637848127232] - session_utils.py[line:109]: init new session failed.
[ERROR] [2020-10-29 08:05:10,106] [6:140637848127232] - session_utils.py[line:100]: session session_used_by_fate_flow_server_768876da19bd11eb9f610242ac120002 count error
Traceback (most recent call last):
  File "/fate/fate_flow/utils/session_utils.py", line 96, in _wrapper
    raise Exception("session {} count error".format(session.get_session_id()))
Exception: session session_used_by_fate_flow_server_768876da19bd11eb9f610242ac120002 count error
[ERROR] [2020-10-29 08:05:10,123] [6:140637848127232] - session_utils.py[line:100]: session session_used_by_fate_flow_server_7702336c19bd11eba9090242ac120002 count error
Traceback (most recent call last):
  File "/fate/fate_flow/utils/session_utils.py", line 96, in _wrapper
    raise Exception("session {} count error".format(session.get_session_id()))
Exception: session session_used_by_fate_flow_server_7702336c19bd11eba9090242ac120002 count error
[ERROR] [2020-10-29 08:05:10,135] [6:140637848127232] - session_utils.py[line:100]: session session_used_by_fate_flow_server_7704ba2e19bd11eba9090242ac120002 count error
Traceback (most recent call last):
  File "/fate/fate_flow/utils/session_utils.py", line 96, in _wrapper
    raise Exception("session {} count error".format(session.get_session_id()))
Exception: session session_used_by_fate_flow_server_7704ba2e19bd11eba9090242ac120002 count error
[ERROR] [2020-10-29 08:05:10,144] [6:140637848127232] - session_utils.py[line:109]: init new session failed.
[ERROR] [2020-10-29 08:05:10,158] [6:140637848127232] - session_utils.py[line:100]: session session_used_by_fate_flow_server_7706a65419bd11eba9090242ac120002 count error
Traceback (most recent call last):
  File "/fate/fate_flow/utils/session_utils.py", line 96, in _wrapper
    raise Exception("session {} count error".format(session.get_session_id()))
Exception: session session_used_by_fate_flow_server_7706a65419bd11eba9090242ac120002 count error
[ERROR] [2020-10-29 08:05:10,170] [6:140637848127232] - session_utils.py[line:100]: session session_used_by_fate_flow_server_770a23c419bd11ebabe50242ac120002 count error
Traceback (most recent call last):
  File "/fate/fate_flow/utils/session_utils.py", line 96, in _wrapper
    raise Exception("session {} count error".format(session.get_session_id()))
Exception: session session_used_by_fate_flow_server_770a23c419bd11ebabe50242ac120002 count error
[ERROR] [2020-10-29 08:05:10,183] [6:140637848127232] - session_utils.py[line:100]: session session_used_by_fate_flow_server_770be59219bd11ebabe50242ac120002 count error
Traceback (most recent call last):
  File "/fate/fate_flow/utils/session_utils.py", line 96, in _wrapper
    raise Exception("session {} count error".format(session.get_session_id()))
Exception: session session_used_by_fate_flow_server_770be59219bd11ebabe50242ac120002 count error
[ERROR] [2020-10-29 08:05:10,194] [6:140637848127232] - session_utils.py[line:109]: init new session failed.
[ERROR] [2020-10-29 08:05:10,210] [6:140637848127232] - session_utils.py[line:100]: session session_used_by_fate_flow_server_770de5ea19bd11ebabe50242ac120002 count error
Traceback (most recent call last):
  File "/fate/fate_flow/utils/session_utils.py", line 96, in _wrapper
    raise Exception("session {} count error".format(session.get_session_id()))
Exception: session session_used_by_fate_flow_server_770de5ea19bd11ebabe50242ac120002 count error
[ERROR] [2020-10-29 08:05:10,222] [6:140637848127232] - session_utils.py[line:100]: session session_used_by_fate_flow_server_77120a3a19bd11eb8bae0242ac120002 count error
Traceback (most recent call last):
  File "/fate/fate_flow/utils/session_utils.py", line 96, in _wrapper
    raise Exception("session {} count error".format(session.get_session_id()))
Exception: session session_used_by_fate_flow_server_77120a3a19bd11eb8bae0242ac120002 count error
[ERROR] [2020-10-29 08:05:10,234] [6:140637848127232] - session_utils.py[line:100]: session session_used_by_fate_flow_server_7713d68a19bd11eb8bae0242ac120002 count error
Traceback (most recent call last):
  File "/fate/fate_flow/utils/session_utils.py", line 96, in _wrapper
    raise Exception("session {} count error".format(session.get_session_id()))
Exception: session session_used_by_fate_flow_server_7713d68a19bd11eb8bae0242ac120002 count error
[ERROR] [2020-10-29 08:05:10,243] [6:140637848127232] - session_utils.py[line:109]: init new session failed.
[ERROR] [2020-10-29 08:05:11,461] [6:140229272925952] - session_utils.py[line:100]: session session_used_by_fate_flow_server_7715adde19bd11eb8bae0242ac120002 count error
Traceback (most recent call last):
  File "/fate/fate_flow/utils/session_utils.py", line 96, in _wrapper
    raise Exception("session {} count error".format(session.get_session_id()))
Exception: session session_used_by_fate_flow_server_7715adde19bd11eb8bae0242ac120002 count error
[ERROR] [2020-10-29 08:05:11,477] [6:140229272925952] - session_utils.py[line:100]: session session_used_by_fate_flow_server_77d103a419bd11ebbb050242ac120002 count error
Traceback (most recent call last):
  File "/fate/fate_flow/utils/session_utils.py", line 96, in _wrapper
    raise Exception("session {} count error".format(session.get_session_id()))
Exception: session session_used_by_fate_flow_server_77d103a419bd11ebbb050242ac120002 count error
[ERROR] [2020-10-29 08:05:11,490] [6:140229272925952] - session_utils.py[line:100]: session session_used_by_fate_flow_server_77d3543819bd11ebbb050242ac120002 count error
Traceback (most recent call last):
  File "/fate/fate_flow/utils/session_utils.py", line 96, in _wrapper
    raise Exception("session {} count error".format(session.get_session_id()))
Exception: session session_used_by_fate_flow_server_77d3543819bd11ebbb050242ac120002 count error
[ERROR] [2020-10-29 08:05:11,501] [6:140229272925952] - session_utils.py[line:109]: init new session failed.
[ERROR] [2020-10-29 08:05:15,312] [6:140229272925952] - session_utils.py[line:100]: session session_used_by_fate_flow_server_77d578d019bd11ebbb050242ac120002 count error
Traceback (most recent call last):
  File "/fate/fate_flow/utils/session_utils.py", line 96, in _wrapper
    raise Exception("session {} count error".format(session.get_session_id()))
Exception: session session_used_by_fate_flow_server_77d578d019bd11ebbb050242ac120002 count error
[ERROR] [2020-10-29 08:05:15,327] [6:140229272925952] - session_utils.py[line:100]: session session_used_by_fate_flow_server_7a1c957e19bd11eb8dca0242ac120002 count error
Traceback (most recent call last):
  File "/fate/fate_flow/utils/session_utils.py", line 96, in _wrapper
    raise Exception("session {} count error".format(session.get_session_id()))
Exception: session session_used_by_fate_flow_server_7a1c957e19bd11eb8dca0242ac120002 count error
[ERROR] [2020-10-29 08:05:15,342] [6:140229272925952] - session_utils.py[line:100]: session session_used_by_fate_flow_server_7a1ed6d619bd11eb8dca0242ac120002 count error
Traceback (most recent call last):
  File "/fate/fate_flow/utils/session_utils.py", line 96, in _wrapper
    raise Exception("session {} count error".format(session.get_session_id()))
Exception: session session_used_by_fate_flow_server_7a1ed6d619bd11eb8dca0242ac120002 count error
[ERROR] [2020-10-29 08:05:15,353] [6:140229272925952] - session_utils.py[line:109]: init new session failed.
[ERROR] [2020-10-29 08:05:15,369] [6:140229272925952] - session_utils.py[line:100]: session session_used_by_fate_flow_server_7a2131ce19bd11eb8dca0242ac120002 count error
Traceback (most recent call last):
  File "/fate/fate_flow/utils/session_utils.py", line 96, in _wrapper
    raise Exception("session {} count error".format(session.get_session_id()))
Exception: session session_used_by_fate_flow_server_7a2131ce19bd11eb8dca0242ac120002 count error
[ERROR] [2020-10-29 08:05:15,384] [6:140229272925952] - session_utils.py[line:100]: session session_used_by_fate_flow_server_7a2531fc19bd11ebb54d0242ac120002 count error
Traceback (most recent call last):
  File "/fate/fate_flow/utils/session_utils.py", line 96, in _wrapper
    raise Exception("session {} count error".format(session.get_session_id()))
Exception: session session_used_by_fate_flow_server_7a2531fc19bd11ebb54d0242ac120002 count error
[ERROR] [2020-10-29 08:05:15,399] [6:140229272925952] - session_utils.py[line:100]: session session_used_by_fate_flow_server_7a27726419bd11ebb54d0242ac120002 count error
Traceback (most recent call last):
  File "/fate/fate_flow/utils/session_utils.py", line 96, in _wrapper
    raise Exception("session {} count error".format(session.get_session_id()))
Exception: session session_used_by_fate_flow_server_7a27726419bd11ebb54d0242ac120002 count error
[ERROR] [2020-10-29 08:05:15,410] [6:140229272925952] - session_utils.py[line:109]: init new session failed.
[ERROR] [2020-10-29 08:05:24,270] [6:140540940003072] - session_utils.py[line:100]: session session_used_by_fate_flow_server_7a29e12a19bd11ebb54d0242ac120002 count error
Traceback (most recent call last):
  File "/fate/fate_flow/utils/session_utils.py", line 96, in _wrapper
    raise Exception("session {} count error".format(session.get_session_id()))
Exception: session session_used_by_fate_flow_server_7a29e12a19bd11ebb54d0242ac120002 count error
[ERROR] [2020-10-29 08:05:24,285] [6:140540940003072] - session_utils.py[line:100]: session session_used_by_fate_flow_server_7f737a2419bd11eb92ea0242ac120002 count error
Traceback (most recent call last):
  File "/fate/fate_flow/utils/session_utils.py", line 96, in _wrapper
    raise Exception("session {} count error".format(session.get_session_id()))
Exception: session session_used_by_fate_flow_server_7f737a2419bd11eb92ea0242ac120002 count error
[ERROR] [2020-10-29 08:05:24,299] [6:140540940003072] - session_utils.py[line:100]: session session_used_by_fate_flow_server_7f75b82a19bd11eb92ea0242ac120002 count error
Traceback (most recent call last):
  File "/fate/fate_flow/utils/session_utils.py", line 96, in _wrapper
    raise Exception("session {} count error".format(session.get_session_id()))
Exception: session session_used_by_fate_flow_server_7f75b82a19bd11eb92ea0242ac120002 count error
[ERROR] [2020-10-29 08:05:24,313] [6:140540940003072] - session_utils.py[line:109]: init new session failed.
[ERROR] [2020-10-29 08:05:24,328] [6:140540940003072] - session_utils.py[line:100]: session session_used_by_fate_flow_server_7f77ebe019bd11eb92ea0242ac120002 count error
Traceback (most recent call last):
  File "/fate/fate_flow/utils/session_utils.py", line 96, in _wrapper
    raise Exception("session {} count error".format(session.get_session_id()))
Exception: session session_used_by_fate_flow_server_7f77ebe019bd11eb92ea0242ac120002 count error
[ERROR] [2020-10-29 08:05:24,342] [6:140540940003072] - session_utils.py[line:100]: session session_used_by_fate_flow_server_7f7c595a19bd11eba9490242ac120002 count error
Traceback (most recent call last):
  File "/fate/fate_flow/utils/session_utils.py", line 96, in _wrapper
    raise Exception("session {} count error".format(session.get_session_id()))
Exception: session session_used_by_fate_flow_server_7f7c595a19bd11eba9490242ac120002 count error
[ERROR] [2020-10-29 08:05:24,356] [6:140540940003072] - session_utils.py[line:100]: session session_used_by_fate_flow_server_7f7e876619bd11eba9490242ac120002 count error
Traceback (most recent call last):
  File "/fate/fate_flow/utils/session_utils.py", line 96, in _wrapper
    raise Exception("session {} count error".format(session.get_session_id()))
Exception: session session_used_by_fate_flow_server_7f7e876619bd11eba9490242ac120002 count error
[ERROR] [2020-10-29 08:05:24,367] [6:140540940003072] - session_utils.py[line:109]: init new session failed.
[ERROR] [2020-10-29 08:05:30,649] [6:140540940003072] - session_utils.py[line:100]: session session_used_by_fate_flow_server_7f80837219bd11eba9490242ac120002 count error
Traceback (most recent call last):
  File "/fate/fate_flow/utils/session_utils.py", line 96, in _wrapper
    raise Exception("session {} count error".format(session.get_session_id()))
Exception: session session_used_by_fate_flow_server_7f80837219bd11eba9490242ac120002 count error
[ERROR] [2020-10-29 08:05:30,665] [6:140540940003072] - session_utils.py[line:100]: session session_used_by_fate_flow_server_8340f3a219bd11ebb0420242ac120002 count error
Traceback (most recent call last):
  File "/fate/fate_flow/utils/session_utils.py", line 96, in _wrapper
    raise Exception("session {} count error".format(session.get_session_id()))
Exception: session session_used_by_fate_flow_server_8340f3a219bd11ebb0420242ac120002 count error
[ERROR] [2020-10-29 08:05:30,678] [6:140540940003072] - session_utils.py[line:100]: session session_used_by_fate_flow_server_8343409419bd11ebb0420242ac120002 count error
Traceback (most recent call last):
  File "/fate/fate_flow/utils/session_utils.py", line 96, in _wrapper
    raise Exception("session {} count error".format(session.get_session_id()))
Exception: session session_used_by_fate_flow_server_8343409419bd11ebb0420242ac120002 count error
[ERROR] [2020-10-29 08:05:30,690] [6:140540940003072] - session_utils.py[line:109]: init new session failed.
[ERROR] [2020-10-29 08:05:30,707] [6:140540940003072] - session_utils.py[line:100]: session session_used_by_fate_flow_server_8345489e19bd11ebb0420242ac120002 count error
Traceback (most recent call last):
  File "/fate/fate_flow/utils/session_utils.py", line 96, in _wrapper
    raise Exception("session {} count error".format(session.get_session_id()))
Exception: session session_used_by_fate_flow_server_8345489e19bd11ebb0420242ac120002 count error
[ERROR] [2020-10-29 08:05:30,721] [6:140540940003072] - session_utils.py[line:100]: session session_used_by_fate_flow_server_8349ae2019bd11eba6710242ac120002 count error
Traceback (most recent call last):
  File "/fate/fate_flow/utils/session_utils.py", line 96, in _wrapper
    raise Exception("session {} count error".format(session.get_session_id()))
Exception: session session_used_by_fate_flow_server_8349ae2019bd11eba6710242ac120002 count error
[ERROR] [2020-10-29 08:05:30,737] [6:140540940003072] - session_utils.py[line:100]: session session_used_by_fate_flow_server_834bcf4819bd11eba6710242ac120002 count error
Traceback (most recent call last):
  File "/fate/fate_flow/utils/session_utils.py", line 96, in _wrapper
    raise Exception("session {} count error".format(session.get_session_id()))
Exception: session session_used_by_fate_flow_server_834bcf4819bd11eba6710242ac120002 count error
[ERROR] [2020-10-29 08:05:30,748] [6:140540940003072] - session_utils.py[line:109]: init new session failed.
[ERROR] [2020-10-29 08:05:30,762] [6:140540940003072] - session_utils.py[line:100]: session session_used_by_fate_flow_server_834e3ac619bd11eba6710242ac120002 count error
Traceback (most recent call last):
  File "/fate/fate_flow/utils/session_utils.py", line 96, in _wrapper
    raise Exception("session {} count error".format(session.get_session_id()))
Exception: session session_used_by_fate_flow_server_834e3ac619bd11eba6710242ac120002 count error
[ERROR] [2020-10-29 08:05:30,776] [6:140540940003072] - session_utils.py[line:100]: session session_used_by_fate_flow_server_835214ca19bd11eb9cc30242ac120002 count error
Traceback (most recent call last):
  File "/fate/fate_flow/utils/session_utils.py", line 96, in _wrapper
    raise Exception("session {} count error".format(session.get_session_id()))
Exception: session session_used_by_fate_flow_server_835214ca19bd11eb9cc30242ac120002 count error
[ERROR] [2020-10-29 08:05:30,789] [6:140540940003072] - session_utils.py[line:100]: session session_used_by_fate_flow_server_8354276019bd11eb9cc30242ac120002 count error
Traceback (most recent call last):
  File "/fate/fate_flow/utils/session_utils.py", line 96, in _wrapper
    raise Exception("session {} count error".format(session.get_session_id()))
Exception: session session_used_by_fate_flow_server_8354276019bd11eb9cc30242ac120002 count error
[ERROR] [2020-10-29 08:05:30,800] [6:140540940003072] - session_utils.py[line:109]: init new session failed.
[ERROR] [2020-10-29 08:06:01,072] [6:140540940003072] - session_utils.py[line:100]: session session_used_by_fate_flow_server_8356284e19bd11eb9cc30242ac120002 count error
Traceback (most recent call last):
  File "/fate/fate_flow/utils/session_utils.py", line 96, in _wrapper
    raise Exception("session {} count error".format(session.get_session_id()))
Exception: session session_used_by_fate_flow_server_8356284e19bd11eb9cc30242ac120002 count error
[ERROR] [2020-10-29 08:06:01,085] [6:140540940003072] - session_utils.py[line:100]: session session_used_by_fate_flow_server_9563025019bd11ebadf60242ac120002 count error
Traceback (most recent call last):
  File "/fate/fate_flow/utils/session_utils.py", line 96, in _wrapper
    raise Exception("session {} count error".format(session.get_session_id()))
Exception: session session_used_by_fate_flow_server_9563025019bd11ebadf60242ac120002 count error
[ERROR] [2020-10-29 08:06:01,100] [6:140540940003072] - session_utils.py[line:100]: session session_used_by_fate_flow_server_9564f35819bd11ebadf60242ac120002 count error
Traceback (most recent call last):
  File "/fate/fate_flow/utils/session_utils.py", line 96, in _wrapper
    raise Exception("session {} count error".format(session.get_session_id()))
Exception: session session_used_by_fate_flow_server_9564f35819bd11ebadf60242ac120002 count error
[ERROR] [2020-10-29 08:06:01,111] [6:140540940003072] - session_utils.py[line:109]: init new session failed.
[ERROR] [2020-10-29 08:06:01,126] [6:140540940003072] - session_utils.py[line:100]: session session_used_by_fate_flow_server_95674d9c19bd11ebadf60242ac120002 count error
Traceback (most recent call last):
  File "/fate/fate_flow/utils/session_utils.py", line 96, in _wrapper
    raise Exception("session {} count error".format(session.get_session_id()))
Exception: session session_used_by_fate_flow_server_95674d9c19bd11ebadf60242ac120002 count error
[ERROR] [2020-10-29 08:06:01,139] [6:140540940003072] - session_utils.py[line:100]: session session_used_by_fate_flow_server_956b36a019bd11ebbcf00242ac120002 count error
Traceback (most recent call last):
  File "/fate/fate_flow/utils/session_utils.py", line 96, in _wrapper
    raise Exception("session {} count error".format(session.get_session_id()))
Exception: session session_used_by_fate_flow_server_956b36a019bd11ebbcf00242ac120002 count error
[ERROR] [2020-10-29 08:06:01,153] [6:140540940003072] - session_utils.py[line:100]: session session_used_by_fate_flow_server_956d256419bd11ebbcf00242ac120002 count error
Traceback (most recent call last):
  File "/fate/fate_flow/utils/session_utils.py", line 96, in _wrapper
    raise Exception("session {} count error".format(session.get_session_id()))
Exception: session session_used_by_fate_flow_server_956d256419bd11ebbcf00242ac120002 count error
[ERROR] [2020-10-29 08:06:01,163] [6:140540940003072] - session_utils.py[line:109]: init new session failed.
[ERROR] [2020-10-29 08:06:04,459] [6:140540940003072] - session_utils.py[line:100]: session session_used_by_fate_flow_server_956f485819bd11ebbcf00242ac120002 count error
Traceback (most recent call last):
  File "/fate/fate_flow/utils/session_utils.py", line 96, in _wrapper
    raise Exception("session {} count error".format(session.get_session_id()))
Exception: session session_used_by_fate_flow_server_956f485819bd11ebbcf00242ac120002 count error
[ERROR] [2020-10-29 08:06:04,475] [6:140540940003072] - session_utils.py[line:100]: session session_used_by_fate_flow_server_97680d4819bd11eb80280242ac120002 count error
Traceback (most recent call last):
  File "/fate/fate_flow/utils/session_utils.py", line 96, in _wrapper
    raise Exception("session {} count error".format(session.get_session_id()))
Exception: session session_used_by_fate_flow_server_97680d4819bd11eb80280242ac120002 count error
[ERROR] [2020-10-29 08:06:04,490] [6:140540940003072] - session_utils.py[line:100]: session session_used_by_fate_flow_server_976a2e3e19bd11eb80280242ac120002 count error
Traceback (most recent call last):
  File "/fate/fate_flow/utils/session_utils.py", line 96, in _wrapper
    raise Exception("session {} count error".format(session.get_session_id()))
Exception: session session_used_by_fate_flow_server_976a2e3e19bd11eb80280242ac120002 count error
[ERROR] [2020-10-29 08:06:04,501] [6:140540940003072] - session_utils.py[line:109]: init new session failed.
[ERROR] [2020-10-29 08:06:04,506] [6:140540940003072] - session_utils.py[line:100]: session session_used_by_fate_flow_server_976c755e19bd11eb80280242ac120002 count error
Traceback (most recent call last):
  File "/fate/fate_flow/utils/session_utils.py", line 96, in _wrapper
    raise Exception("session {} count error".format(session.get_session_id()))
Exception: session session_used_by_fate_flow_server_976c755e19bd11eb80280242ac120002 count error
[ERROR] [2020-10-29 08:06:04,519] [6:140540940003072] - session_utils.py[line:100]: session session_used_by_fate_flow_server_976eeb5e19bd11eb80280242ac120002 count error
Traceback (most recent call last):
  File "/fate/fate_flow/utils/session_utils.py", line 96, in _wrapper
    raise Exception("session {} count error".format(session.get_session_id()))
Exception: session session_used_by_fate_flow_server_976eeb5e19bd11eb80280242ac120002 count error
[ERROR] [2020-10-29 08:06:04,535] [6:140540940003072] - session_utils.py[line:100]: session session_used_by_fate_flow_server_9770fdcc19bd11eb80280242ac120002 count error
Traceback (most recent call last):
  File "/fate/fate_flow/utils/session_utils.py", line 96, in _wrapper
    raise Exception("session {} count error".format(session.get_session_id()))
Exception: session session_used_by_fate_flow_server_9770fdcc19bd11eb80280242ac120002 count error
[ERROR] [2020-10-29 08:06:04,545] [6:140540940003072] - session_utils.py[line:109]: init new session failed.
[ERROR] [2020-10-29 08:06:04,551] [6:140540940003072] - session_utils.py[line:100]: session session_used_by_fate_flow_server_97737b7419bd11eb80280242ac120002 count error
Traceback (most recent call last):
  File "/fate/fate_flow/utils/session_utils.py", line 96, in _wrapper
    raise Exception("session {} count error".format(session.get_session_id()))
Exception: session session_used_by_fate_flow_server_97737b7419bd11eb80280242ac120002 count error
[ERROR] [2020-10-29 08:06:04,567] [6:140540940003072] - session_utils.py[line:100]: session session_used_by_fate_flow_server_9775e1d419bd11eb80280242ac120002 count error
Traceback (most recent call last):
  File "/fate/fate_flow/utils/session_utils.py", line 96, in _wrapper
    raise Exception("session {} count error".format(session.get_session_id()))
Exception: session session_used_by_fate_flow_server_9775e1d419bd11eb80280242ac120002 count error
[ERROR] [2020-10-29 08:06:04,581] [6:140540940003072] - session_utils.py[line:100]: session session_used_by_fate_flow_server_97784c1219bd11eb80280242ac120002 count error
Traceback (most recent call last):
  File "/fate/fate_flow/utils/session_utils.py", line 96, in _wrapper
    raise Exception("session {} count error".format(session.get_session_id()))
Exception: session session_used_by_fate_flow_server_97784c1219bd11eb80280242ac120002 count error
[ERROR] [2020-10-29 08:06:04,592] [6:140540940003072] - session_utils.py[line:109]: init new session failed.
[ERROR] [2020-10-29 08:06:04,597] [6:140540940003072] - session_utils.py[line:100]: session session_used_by_fate_flow_server_977a8e0a19bd11eb80280242ac120002 count error
Traceback (most recent call last):
  File "/fate/fate_flow/utils/session_utils.py", line 96, in _wrapper
    raise Exception("session {} count error".format(session.get_session_id()))
Exception: session session_used_by_fate_flow_server_977a8e0a19bd11eb80280242ac120002 count error
[ERROR] [2020-10-29 08:06:04,612] [6:140540940003072] - session_utils.py[line:100]: session session_used_by_fate_flow_server_977d137819bd11eb80280242ac120002 count error
Traceback (most recent call last):
  File "/fate/fate_flow/utils/session_utils.py", line 96, in _wrapper
    raise Exception("session {} count error".format(session.get_session_id()))
Exception: session session_used_by_fate_flow_server_977d137819bd11eb80280242ac120002 count error
[ERROR] [2020-10-29 08:06:04,628] [6:140540940003072] - session_utils.py[line:100]: session session_used_by_fate_flow_server_977f4dfa19bd11eb80280242ac120002 count error
Traceback (most recent call last):
  File "/fate/fate_flow/utils/session_utils.py", line 96, in _wrapper
    raise Exception("session {} count error".format(session.get_session_id()))
Exception: session session_used_by_fate_flow_server_977f4dfa19bd11eb80280242ac120002 count error
[ERROR] [2020-10-29 08:06:04,639] [6:140540940003072] - session_utils.py[line:109]: init new session failed.
[ERROR] [2020-10-29 08:06:04,647] [6:140540940003072] - session_utils.py[line:100]: session session_used_by_fate_flow_server_9781c09419bd11eb80280242ac120002 count error
Traceback (most recent call last):
  File "/fate/fate_flow/utils/session_utils.py", line 96, in _wrapper
    raise Exception("session {} count error".format(session.get_session_id()))
Exception: session session_used_by_fate_flow_server_9781c09419bd11eb80280242ac120002 count error
[ERROR] [2020-10-29 08:06:04,660] [6:140540940003072] - session_utils.py[line:100]: session session_used_by_fate_flow_server_9784909419bd11eb80280242ac120002 count error
Traceback (most recent call last):
  File "/fate/fate_flow/utils/session_utils.py", line 96, in _wrapper
    raise Exception("session {} count error".format(session.get_session_id()))
Exception: session session_used_by_fate_flow_server_9784909419bd11eb80280242ac120002 count error
[ERROR] [2020-10-29 08:06:04,674] [6:140540940003072] - session_utils.py[line:100]: session session_used_by_fate_flow_server_9786a97e19bd11eb80280242ac120002 count error
Traceback (most recent call last):
  File "/fate/fate_flow/utils/session_utils.py", line 96, in _wrapper
    raise Exception("session {} count error".format(session.get_session_id()))
Exception: session session_used_by_fate_flow_server_9786a97e19bd11eb80280242ac120002 count error
[ERROR] [2020-10-29 08:06:04,685] [6:140540940003072] - session_utils.py[line:109]: init new session failed.
[ERROR] [2020-10-29 08:06:04,743] [6:140540940003072] - session_utils.py[line:100]: session session_used_by_fate_flow_server_9788ce2019bd11eb80280242ac120002 count error
Traceback (most recent call last):
  File "/fate/fate_flow/utils/session_utils.py", line 96, in _wrapper
    raise Exception("session {} count error".format(session.get_session_id()))
Exception: session session_used_by_fate_flow_server_9788ce2019bd11eb80280242ac120002 count error
[ERROR] [2020-10-29 08:06:04,773] [6:140540940003072] - session_utils.py[line:100]: session session_used_by_fate_flow_server_979351e219bd11ebb9e60242ac120002 count error
Traceback (most recent call last):
  File "/fate/fate_flow/utils/session_utils.py", line 96, in _wrapper
    raise Exception("session {} count error".format(session.get_session_id()))
Exception: session session_used_by_fate_flow_server_979351e219bd11ebb9e60242ac120002 count error
[ERROR] [2020-10-29 08:06:04,803] [6:140540940003072] - session_utils.py[line:100]: session session_used_by_fate_flow_server_9797de4219bd11ebb9e60242ac120002 count error
Traceback (most recent call last):
  File "/fate/fate_flow/utils/session_utils.py", line 96, in _wrapper
    raise Exception("session {} count error".format(session.get_session_id()))
Exception: session session_used_by_fate_flow_server_9797de4219bd11ebb9e60242ac120002 count error
[ERROR] [2020-10-29 08:06:04,815] [6:140540940003072] - session_utils.py[line:109]: init new session failed.
[ERROR] [2020-10-29 08:06:04,821] [6:140540940003072] - session_utils.py[line:100]: session session_used_by_fate_flow_server_979c7bdc19bd11ebb9e60242ac120002 count error
Traceback (most recent call last):
  File "/fate/fate_flow/utils/session_utils.py", line 96, in _wrapper
    raise Exception("session {} count error".format(session.get_session_id()))
Exception: session session_used_by_fate_flow_server_979c7bdc19bd11ebb9e60242ac120002 count error
[ERROR] [2020-10-29 08:06:04,839] [6:140540940003072] - session_utils.py[line:100]: session session_used_by_fate_flow_server_979f258a19bd11ebb9e60242ac120002 count error
Traceback (most recent call last):
  File "/fate/fate_flow/utils/session_utils.py", line 96, in _wrapper
    raise Exception("session {} count error".format(session.get_session_id()))
Exception: session session_used_by_fate_flow_server_979f258a19bd11ebb9e60242ac120002 count error
[ERROR] [2020-10-29 08:06:04,867] [6:140540940003072] - session_utils.py[line:100]: session session_used_by_fate_flow_server_97a2d78e19bd11ebb9e60242ac120002 count error
Traceback (most recent call last):
  File "/fate/fate_flow/utils/session_utils.py", line 96, in _wrapper
    raise Exception("session {} count error".format(session.get_session_id()))
Exception: session session_used_by_fate_flow_server_97a2d78e19bd11ebb9e60242ac120002 count error
[ERROR] [2020-10-29 08:06:04,879] [6:140540940003072] - session_utils.py[line:109]: init new session failed.
[ERROR] [2020-10-29 08:06:04,884] [6:140540940003072] - session_utils.py[line:100]: session session_used_by_fate_flow_server_97a6283a19bd11ebb9e60242ac120002 count error
Traceback (most recent call last):
  File "/fate/fate_flow/utils/session_utils.py", line 96, in _wrapper
    raise Exception("session {} count error".format(session.get_session_id()))
Exception: session session_used_by_fate_flow_server_97a6283a19bd11ebb9e60242ac120002 count error
[ERROR] [2020-10-29 08:06:04,898] [6:140540940003072] - session_utils.py[line:100]: session session_used_by_fate_flow_server_97a8c91419bd11ebb9e60242ac120002 count error
Traceback (most recent call last):
  File "/fate/fate_flow/utils/session_utils.py", line 96, in _wrapper
    raise Exception("session {} count error".format(session.get_session_id()))
Exception: session session_used_by_fate_flow_server_97a8c91419bd11ebb9e60242ac120002 count error
[ERROR] [2020-10-29 08:06:04,913] [6:140540940003072] - session_utils.py[line:100]: session session_used_by_fate_flow_server_97aaf1b219bd11ebb9e60242ac120002 count error
Traceback (most recent call last):
  File "/fate/fate_flow/utils/session_utils.py", line 96, in _wrapper
    raise Exception("session {} count error".format(session.get_session_id()))
Exception: session session_used_by_fate_flow_server_97aaf1b219bd11ebb9e60242ac120002 count error
[ERROR] [2020-10-29 08:06:04,923] [6:140540940003072] - session_utils.py[line:109]: init new session failed.
[ERROR] [2020-10-29 08:06:04,927] [6:140540940003072] - session_utils.py[line:100]: session session_used_by_fate_flow_server_97ad31a219bd11ebb9e60242ac120002 count error
Traceback (most recent call last):
  File "/fate/fate_flow/utils/session_utils.py", line 96, in _wrapper
    raise Exception("session {} count error".format(session.get_session_id()))
Exception: session session_used_by_fate_flow_server_97ad31a219bd11ebb9e60242ac120002 count error
[ERROR] [2020-10-29 08:06:04,943] [6:140540940003072] - session_utils.py[line:100]: session session_used_by_fate_flow_server_97af62ec19bd11ebb9e60242ac120002 count error
Traceback (most recent call last):
  File "/fate/fate_flow/utils/session_utils.py", line 96, in _wrapper
    raise Exception("session {} count error".format(session.get_session_id()))
Exception: session session_used_by_fate_flow_server_97af62ec19bd11ebb9e60242ac120002 count error
[ERROR] [2020-10-29 08:06:04,959] [6:140540940003072] - session_utils.py[line:100]: session session_used_by_fate_flow_server_97b1c97419bd11ebb9e60242ac120002 count error
Traceback (most recent call last):
  File "/fate/fate_flow/utils/session_utils.py", line 96, in _wrapper
    raise Exception("session {} count error".format(session.get_session_id()))
Exception: session session_used_by_fate_flow_server_97b1c97419bd11ebb9e60242ac120002 count error
[ERROR] [2020-10-29 08:06:04,972] [6:140540940003072] - session_utils.py[line:109]: init new session failed.
[ERROR] [2020-10-29 08:06:04,977] [6:140540940003072] - session_utils.py[line:100]: session session_used_by_fate_flow_server_97b459e619bd11ebb9e60242ac120002 count error
Traceback (most recent call last):
  File "/fate/fate_flow/utils/session_utils.py", line 96, in _wrapper
    raise Exception("session {} count error".format(session.get_session_id()))
Exception: session session_used_by_fate_flow_server_97b459e619bd11ebb9e60242ac120002 count error
[ERROR] [2020-10-29 08:06:04,995] [6:140540940003072] - session_utils.py[line:100]: session session_used_by_fate_flow_server_97b6f9f819bd11ebb9e60242ac120002 count error
Traceback (most recent call last):
  File "/fate/fate_flow/utils/session_utils.py", line 96, in _wrapper
    raise Exception("session {} count error".format(session.get_session_id()))
Exception: session session_used_by_fate_flow_server_97b6f9f819bd11ebb9e60242ac120002 count error
[ERROR] [2020-10-29 08:06:05,010] [6:140540940003072] - session_utils.py[line:100]: session session_used_by_fate_flow_server_97b9d6fa19bd11ebb9e60242ac120002 count error
Traceback (most recent call last):
  File "/fate/fate_flow/utils/session_utils.py", line 96, in _wrapper
    raise Exception("session {} count error".format(session.get_session_id()))
Exception: session session_used_by_fate_flow_server_97b9d6fa19bd11ebb9e60242ac120002 count error
[ERROR] [2020-10-29 08:06:05,022] [6:140540940003072] - session_utils.py[line:109]: init new session failed.
[ERROR] [2020-10-29 08:06:05,071] [6:140540940003072] - session_utils.py[line:100]: session session_used_by_fate_flow_server_97bc0b3219bd11ebb9e60242ac120002 count error
Traceback (most recent call last):
  File "/fate/fate_flow/utils/session_utils.py", line 96, in _wrapper
    raise Exception("session {} count error".format(session.get_session_id()))
Exception: session session_used_by_fate_flow_server_97bc0b3219bd11ebb9e60242ac120002 count error
[ERROR] [2020-10-29 08:06:05,085] [6:140540940003072] - session_utils.py[line:100]: session session_used_by_fate_flow_server_97c54ee019bd11eba05f0242ac120002 count error
Traceback (most recent call last):
  File "/fate/fate_flow/utils/session_utils.py", line 96, in _wrapper
    raise Exception("session {} count error".format(session.get_session_id()))
Exception: session session_used_by_fate_flow_server_97c54ee019bd11eba05f0242ac120002 count error
[ERROR] [2020-10-29 08:06:05,099] [6:140540940003072] - session_utils.py[line:100]: session session_used_by_fate_flow_server_97c7622019bd11eba05f0242ac120002 count error
Traceback (most recent call last):
  File "/fate/fate_flow/utils/session_utils.py", line 96, in _wrapper
    raise Exception("session {} count error".format(session.get_session_id()))
Exception: session session_used_by_fate_flow_server_97c7622019bd11eba05f0242ac120002 count error
[ERROR] [2020-10-29 08:06:05,110] [6:140540940003072] - session_utils.py[line:109]: init new session failed.
[ERROR] [2020-10-29 08:06:13,312] [6:140637848127232] - session_utils.py[line:100]: session session_used_by_fate_flow_server_97c9a4a419bd11eba05f0242ac120002 count error
Traceback (most recent call last):
  File "/fate/fate_flow/utils/session_utils.py", line 96, in _wrapper
    raise Exception("session {} count error".format(session.get_session_id()))
Exception: session session_used_by_fate_flow_server_97c9a4a419bd11eba05f0242ac120002 count error
[ERROR] [2020-10-29 08:06:13,328] [6:140637848127232] - session_utils.py[line:100]: session session_used_by_fate_flow_server_9caed52019bd11eb88c80242ac120002 count error
Traceback (most recent call last):
  File "/fate/fate_flow/utils/session_utils.py", line 96, in _wrapper
    raise Exception("session {} count error".format(session.get_session_id()))
Exception: session session_used_by_fate_flow_server_9caed52019bd11eb88c80242ac120002 count error
[ERROR] [2020-10-29 08:06:13,341] [6:140637848127232] - session_utils.py[line:100]: session session_used_by_fate_flow_server_9cb12c1c19bd11eb88c80242ac120002 count error
Traceback (most recent call last):
  File "/fate/fate_flow/utils/session_utils.py", line 96, in _wrapper
    raise Exception("session {} count error".format(session.get_session_id()))
Exception: session session_used_by_fate_flow_server_9cb12c1c19bd11eb88c80242ac120002 count error
[ERROR] [2020-10-29 08:06:13,352] [6:140637848127232] - session_utils.py[line:109]: init new session failed.
[ERROR] [2020-10-29 08:06:13,394] [6:140637848127232] - session_utils.py[line:100]: session session_used_by_fate_flow_server_9cb335ca19bd11eb88c80242ac120002 count error
Traceback (most recent call last):
  File "/fate/fate_flow/utils/session_utils.py", line 96, in _wrapper
    raise Exception("session {} count error".format(session.get_session_id()))
Exception: session session_used_by_fate_flow_server_9cb335ca19bd11eb88c80242ac120002 count error
[ERROR] [2020-10-29 08:06:13,409] [6:140637848127232] - session_utils.py[line:100]: session session_used_by_fate_flow_server_9cbb3f9019bd11eb91190242ac120002 count error
Traceback (most recent call last):
  File "/fate/fate_flow/utils/session_utils.py", line 96, in _wrapper
    raise Exception("session {} count error".format(session.get_session_id()))
Exception: session session_used_by_fate_flow_server_9cbb3f9019bd11eb91190242ac120002 count error
[ERROR] [2020-10-29 08:06:13,424] [6:140637848127232] - session_utils.py[line:100]: session session_used_by_fate_flow_server_9cbd9af619bd11eb91190242ac120002 count error
Traceback (most recent call last):
  File "/fate/fate_flow/utils/session_utils.py", line 96, in _wrapper
    raise Exception("session {} count error".format(session.get_session_id()))
Exception: session session_used_by_fate_flow_server_9cbd9af619bd11eb91190242ac120002 count error
[ERROR] [2020-10-29 08:06:13,436] [6:140637848127232] - session_utils.py[line:109]: init new session failed.
[ERROR] [2020-10-29 08:09:36,155] [6:140637848127232] - session_utils.py[line:100]: session session_used_by_fate_flow_server_9cbfd50019bd11eb91190242ac120002 count error
Traceback (most recent call last):
  File "/fate/fate_flow/utils/session_utils.py", line 96, in _wrapper
    raise Exception("session {} count error".format(session.get_session_id()))
Exception: session session_used_by_fate_flow_server_9cbfd50019bd11eb91190242ac120002 count error
[ERROR] [2020-10-29 08:09:36,169] [6:140637848127232] - session_utils.py[line:100]: session session_used_by_fate_flow_server_159636cc19be11eba7df0242ac120002 count error
Traceback (most recent call last):
  File "/fate/fate_flow/utils/session_utils.py", line 96, in _wrapper
    raise Exception("session {} count error".format(session.get_session_id()))
Exception: session session_used_by_fate_flow_server_159636cc19be11eba7df0242ac120002 count error
[ERROR] [2020-10-29 08:09:36,183] [6:140637848127232] - session_utils.py[line:100]: session session_used_by_fate_flow_server_1598476e19be11eba7df0242ac120002 count error
Traceback (most recent call last):
  File "/fate/fate_flow/utils/session_utils.py", line 96, in _wrapper
    raise Exception("session {} count error".format(session.get_session_id()))
Exception: session session_used_by_fate_flow_server_1598476e19be11eba7df0242ac120002 count error
[ERROR] [2020-10-29 08:09:36,194] [6:140637848127232] - session_utils.py[line:109]: init new session failed.
[ERROR] [2020-10-29 08:09:37,410] [6:140637848127232] - session_utils.py[line:100]: session session_used_by_fate_flow_server_159a6d1419be11eba7df0242ac120002 count error
Traceback (most recent call last):
  File "/fate/fate_flow/utils/session_utils.py", line 96, in _wrapper
    raise Exception("session {} count error".format(session.get_session_id()))
Exception: session session_used_by_fate_flow_server_159a6d1419be11eba7df0242ac120002 count error
[ERROR] [2020-10-29 08:09:37,426] [6:140637848127232] - session_utils.py[line:100]: session session_used_by_fate_flow_server_1655aa4819be11eb80e20242ac120002 count error
Traceback (most recent call last):
  File "/fate/fate_flow/utils/session_utils.py", line 96, in _wrapper
    raise Exception("session {} count error".format(session.get_session_id()))
Exception: session session_used_by_fate_flow_server_1655aa4819be11eb80e20242ac120002 count error
[ERROR] [2020-10-29 08:09:37,442] [6:140637848127232] - session_utils.py[line:100]: session session_used_by_fate_flow_server_165812ec19be11eb80e20242ac120002 count error
Traceback (most recent call last):
  File "/fate/fate_flow/utils/session_utils.py", line 96, in _wrapper
    raise Exception("session {} count error".format(session.get_session_id()))
Exception: session session_used_by_fate_flow_server_165812ec19be11eb80e20242ac120002 count error
[ERROR] [2020-10-29 08:09:37,455] [6:140637848127232] - session_utils.py[line:109]: init new session failed.
[ERROR] [2020-10-29 08:09:48,837] [6:140637848127232] - session_utils.py[line:100]: session session_used_by_fate_flow_server_165a8a2219be11eb80e20242ac120002 count error
Traceback (most recent call last):
  File "/fate/fate_flow/utils/session_utils.py", line 96, in _wrapper
    raise Exception("session {} count error".format(session.get_session_id()))
Exception: session session_used_by_fate_flow_server_165a8a2219be11eb80e20242ac120002 count error
[ERROR] [2020-10-29 08:09:48,849] [6:140637848127232] - session_utils.py[line:100]: session session_used_by_fate_flow_server_1d253a7819be11eb9a160242ac120002 count error
Traceback (most recent call last):
  File "/fate/fate_flow/utils/session_utils.py", line 96, in _wrapper
    raise Exception("session {} count error".format(session.get_session_id()))
Exception: session session_used_by_fate_flow_server_1d253a7819be11eb9a160242ac120002 count error
[ERROR] [2020-10-29 08:09:48,863] [6:140637848127232] - session_utils.py[line:100]: session session_used_by_fate_flow_server_1d2725fe19be11eb9a160242ac120002 count error
Traceback (most recent call last):
  File "/fate/fate_flow/utils/session_utils.py", line 96, in _wrapper
    raise Exception("session {} count error".format(session.get_session_id()))
Exception: session session_used_by_fate_flow_server_1d2725fe19be11eb9a160242ac120002 count error
[ERROR] [2020-10-29 08:09:48,875] [6:140637848127232] - session_utils.py[line:109]: init new session failed.
[ERROR] [2020-10-29 08:09:50,092] [6:140229272925952] - session_utils.py[line:100]: session session_used_by_fate_flow_server_1d29480219be11eb9a160242ac120002 count error
Traceback (most recent call last):
  File "/fate/fate_flow/utils/session_utils.py", line 96, in _wrapper
    raise Exception("session {} count error".format(session.get_session_id()))
Exception: session session_used_by_fate_flow_server_1d29480219be11eb9a160242ac120002 count error
[ERROR] [2020-10-29 08:09:50,109] [6:140229272925952] - session_utils.py[line:100]: session session_used_by_fate_flow_server_1de4f21e19be11ebabf20242ac120002 count error
Traceback (most recent call last):
  File "/fate/fate_flow/utils/session_utils.py", line 96, in _wrapper
    raise Exception("session {} count error".format(session.get_session_id()))
Exception: session session_used_by_fate_flow_server_1de4f21e19be11ebabf20242ac120002 count error
[ERROR] [2020-10-29 08:09:50,125] [6:140229272925952] - session_utils.py[line:100]: session session_used_by_fate_flow_server_1de76eae19be11ebabf20242ac120002 count error
Traceback (most recent call last):
  File "/fate/fate_flow/utils/session_utils.py", line 96, in _wrapper
    raise Exception("session {} count error".format(session.get_session_id()))
Exception: session session_used_by_fate_flow_server_1de76eae19be11ebabf20242ac120002 count error
[ERROR] [2020-10-29 08:09:50,137] [6:140229272925952] - session_utils.py[line:109]: init new session failed.
[ERROR] [2020-10-29 08:12:06,939] [6:140229272925952] - session_utils.py[line:100]: session session_used_by_fate_flow_server_1de9d7b619be11ebabf20242ac120002 count error
Traceback (most recent call last):
  File "/fate/fate_flow/utils/session_utils.py", line 96, in _wrapper
    raise Exception("session {} count error".format(session.get_session_id()))
Exception: session session_used_by_fate_flow_server_1de9d7b619be11ebabf20242ac120002 count error
[ERROR] [2020-10-29 08:12:06,957] [6:140229272925952] - session_utils.py[line:100]: session session_used_by_fate_flow_server_6f760a8c19be11eb97780242ac120002 count error
Traceback (most recent call last):
  File "/fate/fate_flow/utils/session_utils.py", line 96, in _wrapper
    raise Exception("session {} count error".format(session.get_session_id()))
Exception: session session_used_by_fate_flow_server_6f760a8c19be11eb97780242ac120002 count error
[ERROR] [2020-10-29 08:12:06,974] [6:140229272925952] - session_utils.py[line:100]: session session_used_by_fate_flow_server_6f78c6a019be11eb97780242ac120002 count error
Traceback (most recent call last):
  File "/fate/fate_flow/utils/session_utils.py", line 96, in _wrapper
    raise Exception("session {} count error".format(session.get_session_id()))
Exception: session session_used_by_fate_flow_server_6f78c6a019be11eb97780242ac120002 count error
[ERROR] [2020-10-29 08:12:06,989] [6:140229272925952] - session_utils.py[line:109]: init new session failed.
[ERROR] [2020-10-29 08:12:06,996] [6:140229272925952] - session_utils.py[line:100]: session session_used_by_fate_flow_server_6f7b5bfe19be11eb97780242ac120002 count error
Traceback (most recent call last):
  File "/fate/fate_flow/utils/session_utils.py", line 96, in _wrapper
    raise Exception("session {} count error".format(session.get_session_id()))
Exception: session session_used_by_fate_flow_server_6f7b5bfe19be11eb97780242ac120002 count error
[ERROR] [2020-10-29 08:12:07,014] [6:140229272925952] - session_utils.py[line:100]: session session_used_by_fate_flow_server_6f7ef05c19be11eb97780242ac120002 count error
Traceback (most recent call last):
  File "/fate/fate_flow/utils/session_utils.py", line 96, in _wrapper
    raise Exception("session {} count error".format(session.get_session_id()))
Exception: session session_used_by_fate_flow_server_6f7ef05c19be11eb97780242ac120002 count error
[ERROR] [2020-10-29 08:12:07,031] [6:140229272925952] - session_utils.py[line:100]: session session_used_by_fate_flow_server_6f81769c19be11eb97780242ac120002 count error
Traceback (most recent call last):
  File "/fate/fate_flow/utils/session_utils.py", line 96, in _wrapper
    raise Exception("session {} count error".format(session.get_session_id()))
Exception: session session_used_by_fate_flow_server_6f81769c19be11eb97780242ac120002 count error
[ERROR] [2020-10-29 08:12:07,044] [6:140229272925952] - session_utils.py[line:109]: init new session failed.
[ERROR] [2020-10-29 08:12:07,103] [6:140229272925952] - session_utils.py[line:100]: session session_used_by_fate_flow_server_6f84133419be11eb97780242ac120002 count error
Traceback (most recent call last):
  File "/fate/fate_flow/utils/session_utils.py", line 96, in _wrapper
    raise Exception("session {} count error".format(session.get_session_id()))
Exception: session session_used_by_fate_flow_server_6f84133419be11eb97780242ac120002 count error
[ERROR] [2020-10-29 08:12:07,127] [6:140229272925952] - session_utils.py[line:100]: session session_used_by_fate_flow_server_6f8ed46819be11eb9ec90242ac120002 count error
Traceback (most recent call last):
  File "/fate/fate_flow/utils/session_utils.py", line 96, in _wrapper
    raise Exception("session {} count error".format(session.get_session_id()))
Exception: session session_used_by_fate_flow_server_6f8ed46819be11eb9ec90242ac120002 count error
[ERROR] [2020-10-29 08:12:07,153] [6:140229272925952] - session_utils.py[line:100]: session session_used_by_fate_flow_server_6f928fcc19be11eb9ec90242ac120002 count error
Traceback (most recent call last):
  File "/fate/fate_flow/utils/session_utils.py", line 96, in _wrapper
    raise Exception("session {} count error".format(session.get_session_id()))
Exception: session session_used_by_fate_flow_server_6f928fcc19be11eb9ec90242ac120002 count error
[ERROR] [2020-10-29 08:12:07,215] [6:140229272925952] - session_utils.py[line:109]: init new session failed.
[ERROR] [2020-10-29 08:12:07,221] [6:140229272925952] - session_utils.py[line:100]: session session_used_by_fate_flow_server_6f9685aa19be11eb9ec90242ac120002 count error
Traceback (most recent call last):
  File "/fate/fate_flow/utils/session_utils.py", line 96, in _wrapper
    raise Exception("session {} count error".format(session.get_session_id()))
Exception: session session_used_by_fate_flow_server_6f9685aa19be11eb9ec90242ac120002 count error
[ERROR] [2020-10-29 08:12:07,236] [6:140229272925952] - session_utils.py[line:100]: session session_used_by_fate_flow_server_6fa0d87019be11eb9ec90242ac120002 count error
Traceback (most recent call last):
  File "/fate/fate_flow/utils/session_utils.py", line 96, in _wrapper
    raise Exception("session {} count error".format(session.get_session_id()))
Exception: session session_used_by_fate_flow_server_6fa0d87019be11eb9ec90242ac120002 count error
[ERROR] [2020-10-29 08:12:07,251] [6:140229272925952] - session_utils.py[line:100]: session session_used_by_fate_flow_server_6fa33a3e19be11eb9ec90242ac120002 count error
Traceback (most recent call last):
  File "/fate/fate_flow/utils/session_utils.py", line 96, in _wrapper
    raise Exception("session {} count error".format(session.get_session_id()))
Exception: session session_used_by_fate_flow_server_6fa33a3e19be11eb9ec90242ac120002 count error
[ERROR] [2020-10-29 08:12:07,261] [6:140229272925952] - session_utils.py[line:109]: init new session failed.
[ERROR] [2020-10-29 08:26:07,069] [6:140540940003072] - session_utils.py[line:100]: session session_used_by_fate_flow_server_6fa57c5e19be11eb9ec90242ac120002 count error
Traceback (most recent call last):
  File "/fate/fate_flow/utils/session_utils.py", line 96, in _wrapper
    raise Exception("session {} count error".format(session.get_session_id()))
Exception: session session_used_by_fate_flow_server_6fa57c5e19be11eb9ec90242ac120002 count error
[ERROR] [2020-10-29 08:26:07,084] [6:140540940003072] - session_utils.py[line:100]: session session_used_by_fate_flow_server_64379d6e19c011eb82990242ac120002 count error
Traceback (most recent call last):
  File "/fate/fate_flow/utils/session_utils.py", line 96, in _wrapper
    raise Exception("session {} count error".format(session.get_session_id()))
Exception: session session_used_by_fate_flow_server_64379d6e19c011eb82990242ac120002 count error
[ERROR] [2020-10-29 08:26:07,098] [6:140540940003072] - session_utils.py[line:100]: session session_used_by_fate_flow_server_6439c46819c011eb82990242ac120002 count error
Traceback (most recent call last):
  File "/fate/fate_flow/utils/session_utils.py", line 96, in _wrapper
    raise Exception("session {} count error".format(session.get_session_id()))
Exception: session session_used_by_fate_flow_server_6439c46819c011eb82990242ac120002 count error
[ERROR] [2020-10-29 08:26:07,111] [6:140540940003072] - session_utils.py[line:109]: init new session failed.
[ERROR] [2020-10-29 08:26:07,126] [6:140540940003072] - session_utils.py[line:100]: session session_used_by_fate_flow_server_643bdf9619c011eb82990242ac120002 count error
Traceback (most recent call last):
  File "/fate/fate_flow/utils/session_utils.py", line 96, in _wrapper
    raise Exception("session {} count error".format(session.get_session_id()))
Exception: session session_used_by_fate_flow_server_643bdf9619c011eb82990242ac120002 count error
[ERROR] [2020-10-29 08:26:07,140] [6:140540940003072] - session_utils.py[line:100]: session session_used_by_fate_flow_server_6440405e19c011ebbe430242ac120002 count error
Traceback (most recent call last):
  File "/fate/fate_flow/utils/session_utils.py", line 96, in _wrapper
    raise Exception("session {} count error".format(session.get_session_id()))
Exception: session session_used_by_fate_flow_server_6440405e19c011ebbe430242ac120002 count error
[ERROR] [2020-10-29 08:26:07,153] [6:140540940003072] - session_utils.py[line:100]: session session_used_by_fate_flow_server_64425e2a19c011ebbe430242ac120002 count error
Traceback (most recent call last):
  File "/fate/fate_flow/utils/session_utils.py", line 96, in _wrapper
    raise Exception("session {} count error".format(session.get_session_id()))
Exception: session session_used_by_fate_flow_server_64425e2a19c011ebbe430242ac120002 count error
[ERROR] [2020-10-29 08:26:07,164] [6:140540940003072] - session_utils.py[line:109]: init new session failed.
[ERROR] [2020-10-29 08:26:07,181] [6:140540940003072] - session_utils.py[line:100]: session session_used_by_fate_flow_server_6444559019c011ebbe430242ac120002 count error
Traceback (most recent call last):
  File "/fate/fate_flow/utils/session_utils.py", line 96, in _wrapper
    raise Exception("session {} count error".format(session.get_session_id()))
Exception: session session_used_by_fate_flow_server_6444559019c011ebbe430242ac120002 count error
[ERROR] [2020-10-29 08:26:07,196] [6:140540940003072] - session_utils.py[line:100]: session session_used_by_fate_flow_server_6448c98619c011eb87b00242ac120002 count error
Traceback (most recent call last):
  File "/fate/fate_flow/utils/session_utils.py", line 96, in _wrapper
    raise Exception("session {} count error".format(session.get_session_id()))
Exception: session session_used_by_fate_flow_server_6448c98619c011eb87b00242ac120002 count error
[ERROR] [2020-10-29 08:26:07,211] [6:140540940003072] - session_utils.py[line:100]: session session_used_by_fate_flow_server_644af59419c011eb87b00242ac120002 count error
Traceback (most recent call last):
  File "/fate/fate_flow/utils/session_utils.py", line 96, in _wrapper
    raise Exception("session {} count error".format(session.get_session_id()))
Exception: session session_used_by_fate_flow_server_644af59419c011eb87b00242ac120002 count error
[ERROR] [2020-10-29 08:26:07,224] [6:140540940003072] - session_utils.py[line:109]: init new session failed.
[ERROR] [2020-10-29 08:26:25,773] [6:140540940003072] - session_utils.py[line:100]: session session_used_by_fate_flow_server_644d79ea19c011eb87b00242ac120002 count error
Traceback (most recent call last):
  File "/fate/fate_flow/utils/session_utils.py", line 96, in _wrapper
    raise Exception("session {} count error".format(session.get_session_id()))
Exception: session session_used_by_fate_flow_server_644d79ea19c011eb87b00242ac120002 count error
[ERROR] [2020-10-29 08:26:25,851] [6:140540940003072] - session_utils.py[line:100]: session session_used_by_fate_flow_server_6f5dc51019c011eb843e0242ac120002 count error
Traceback (most recent call last):
  File "/fate/fate_flow/utils/session_utils.py", line 96, in _wrapper
    raise Exception("session {} count error".format(session.get_session_id()))
Exception: session session_used_by_fate_flow_server_6f5dc51019c011eb843e0242ac120002 count error
[ERROR] [2020-10-29 08:26:25,874] [6:140540940003072] - session_utils.py[line:100]: session session_used_by_fate_flow_server_6f6af17219c011eb843e0242ac120002 count error
Traceback (most recent call last):
  File "/fate/fate_flow/utils/session_utils.py", line 96, in _wrapper
    raise Exception("session {} count error".format(session.get_session_id()))
Exception: session session_used_by_fate_flow_server_6f6af17219c011eb843e0242ac120002 count error
[ERROR] [2020-10-29 08:26:25,896] [6:140540940003072] - session_utils.py[line:109]: init new session failed.
[ERROR] [2020-10-29 08:26:25,902] [6:140540940003072] - session_utils.py[line:100]: session session_used_by_fate_flow_server_6f6d107419c011eb843e0242ac120002 count error
Traceback (most recent call last):
  File "/fate/fate_flow/utils/session_utils.py", line 96, in _wrapper
    raise Exception("session {} count error".format(session.get_session_id()))
Exception: session session_used_by_fate_flow_server_6f6d107419c011eb843e0242ac120002 count error
[ERROR] [2020-10-29 08:26:25,947] [6:140540940003072] - session_utils.py[line:100]: session session_used_by_fate_flow_server_6f71547219c011eb843e0242ac120002 count error
Traceback (most recent call last):
  File "/fate/fate_flow/utils/session_utils.py", line 96, in _wrapper
    raise Exception("session {} count error".format(session.get_session_id()))
Exception: session session_used_by_fate_flow_server_6f71547219c011eb843e0242ac120002 count error
[ERROR] [2020-10-29 08:26:25,963] [6:140540940003072] - session_utils.py[line:100]: session session_used_by_fate_flow_server_6f783a5819c011eb843e0242ac120002 count error
Traceback (most recent call last):
  File "/fate/fate_flow/utils/session_utils.py", line 96, in _wrapper
    raise Exception("session {} count error".format(session.get_session_id()))
Exception: session session_used_by_fate_flow_server_6f783a5819c011eb843e0242ac120002 count error
[ERROR] [2020-10-29 08:26:25,975] [6:140540940003072] - session_utils.py[line:109]: init new session failed.
[ERROR] [2020-10-29 08:26:26,029] [6:140229272925952] - session_utils.py[line:100]: session session_used_by_fate_flow_server_6f7ab74c19c011eb843e0242ac120002 count error
Traceback (most recent call last):
  File "/fate/fate_flow/utils/session_utils.py", line 96, in _wrapper
    raise Exception("session {} count error".format(session.get_session_id()))
Exception: session session_used_by_fate_flow_server_6f7ab74c19c011eb843e0242ac120002 count error
[ERROR] [2020-10-29 08:26:26,071] [6:140229272925952] - session_utils.py[line:100]: session session_used_by_fate_flow_server_6f84c5f219c011eb9ccc0242ac120002 count error
Traceback (most recent call last):
  File "/fate/fate_flow/utils/session_utils.py", line 96, in _wrapper
    raise Exception("session {} count error".format(session.get_session_id()))
Exception: session session_used_by_fate_flow_server_6f84c5f219c011eb9ccc0242ac120002 count error
[ERROR] [2020-10-29 08:26:26,114] [6:140229272925952] - session_utils.py[line:100]: session session_used_by_fate_flow_server_6f8b2e0619c011eb9ccc0242ac120002 count error
Traceback (most recent call last):
  File "/fate/fate_flow/utils/session_utils.py", line 96, in _wrapper
    raise Exception("session {} count error".format(session.get_session_id()))
Exception: session session_used_by_fate_flow_server_6f8b2e0619c011eb9ccc0242ac120002 count error
[ERROR] [2020-10-29 08:26:26,213] [6:140229272925952] - session_utils.py[line:109]: init new session failed.
[ERROR] [2020-10-29 08:26:26,224] [6:140229272925952] - session_utils.py[line:100]: session session_used_by_fate_flow_server_6f91b1ae19c011eb9ccc0242ac120002 count error
Traceback (most recent call last):
  File "/fate/fate_flow/utils/session_utils.py", line 96, in _wrapper
    raise Exception("session {} count error".format(session.get_session_id()))
Exception: session session_used_by_fate_flow_server_6f91b1ae19c011eb9ccc0242ac120002 count error
[ERROR] [2020-10-29 08:26:26,245] [6:140229272925952] - session_utils.py[line:100]: session session_used_by_fate_flow_server_6fa282c219c011eb9ccc0242ac120002 count error
Traceback (most recent call last):
  File "/fate/fate_flow/utils/session_utils.py", line 96, in _wrapper
    raise Exception("session {} count error".format(session.get_session_id()))
Exception: session session_used_by_fate_flow_server_6fa282c219c011eb9ccc0242ac120002 count error
[ERROR] [2020-10-29 08:26:26,278] [6:140229272925952] - session_utils.py[line:100]: session session_used_by_fate_flow_server_6fa5bf1419c011eb9ccc0242ac120002 count error
Traceback (most recent call last):
  File "/fate/fate_flow/utils/session_utils.py", line 96, in _wrapper
    raise Exception("session {} count error".format(session.get_session_id()))
Exception: session session_used_by_fate_flow_server_6fa5bf1419c011eb9ccc0242ac120002 count error
[ERROR] [2020-10-29 08:26:26,314] [6:140229272925952] - session_utils.py[line:109]: init new session failed.
[ERROR] [2020-10-29 08:26:26,348] [6:140229272925952] - session_utils.py[line:100]: session session_used_by_fate_flow_server_6fab437619c011eb9ccc0242ac120002 count error
Traceback (most recent call last):
  File "/fate/fate_flow/utils/session_utils.py", line 96, in _wrapper
    raise Exception("session {} count error".format(session.get_session_id()))
Exception: session session_used_by_fate_flow_server_6fab437619c011eb9ccc0242ac120002 count error
[ERROR] [2020-10-29 08:26:26,367] [6:140229272925952] - session_utils.py[line:100]: session session_used_by_fate_flow_server_6fb58f9819c011eb80ef0242ac120002 count error
Traceback (most recent call last):
  File "/fate/fate_flow/utils/session_utils.py", line 96, in _wrapper
    raise Exception("session {} count error".format(session.get_session_id()))
Exception: session session_used_by_fate_flow_server_6fb58f9819c011eb80ef0242ac120002 count error
[ERROR] [2020-10-29 08:26:26,384] [6:140229272925952] - session_utils.py[line:100]: session session_used_by_fate_flow_server_6fb86d8019c011eb80ef0242ac120002 count error
Traceback (most recent call last):
  File "/fate/fate_flow/utils/session_utils.py", line 96, in _wrapper
    raise Exception("session {} count error".format(session.get_session_id()))
Exception: session session_used_by_fate_flow_server_6fb86d8019c011eb80ef0242ac120002 count error
[ERROR] [2020-10-29 08:26:26,397] [6:140229272925952] - session_utils.py[line:109]: init new session failed.
[ERROR] [2020-10-29 08:33:07,378] [6:140637848127232] - session_utils.py[line:100]: session session_used_by_fate_flow_server_6fbafbc219c011eb80ef0242ac120002 count error
Traceback (most recent call last):
  File "/fate/fate_flow/utils/session_utils.py", line 96, in _wrapper
    raise Exception("session {} count error".format(session.get_session_id()))
Exception: session session_used_by_fate_flow_server_6fbafbc219c011eb80ef0242ac120002 count error
[ERROR] [2020-10-29 08:33:07,395] [6:140637848127232] - session_utils.py[line:100]: session session_used_by_fate_flow_server_5ebde3ce19c111eb958c0242ac120002 count error
Traceback (most recent call last):
  File "/fate/fate_flow/utils/session_utils.py", line 96, in _wrapper
    raise Exception("session {} count error".format(session.get_session_id()))
Exception: session session_used_by_fate_flow_server_5ebde3ce19c111eb958c0242ac120002 count error
[ERROR] [2020-10-29 08:33:07,410] [6:140637848127232] - session_utils.py[line:100]: session session_used_by_fate_flow_server_5ec0418219c111eb958c0242ac120002 count error
Traceback (most recent call last):
  File "/fate/fate_flow/utils/session_utils.py", line 96, in _wrapper
    raise Exception("session {} count error".format(session.get_session_id()))
Exception: session session_used_by_fate_flow_server_5ec0418219c111eb958c0242ac120002 count error
[ERROR] [2020-10-29 08:33:07,422] [6:140637848127232] - session_utils.py[line:109]: init new session failed.
[ERROR] [2020-10-29 08:35:56,639] [6:140637848127232] - session_utils.py[line:100]: session session_used_by_fate_flow_server_5ec2b07019c111eb958c0242ac120002 count error
Traceback (most recent call last):
  File "/fate/fate_flow/utils/session_utils.py", line 96, in _wrapper
    raise Exception("session {} count error".format(session.get_session_id()))
Exception: session session_used_by_fate_flow_server_5ec2b07019c111eb958c0242ac120002 count error
[ERROR] [2020-10-29 08:35:56,654] [6:140637848127232] - session_utils.py[line:100]: session session_used_by_fate_flow_server_c3a0f89e19c111ebb5cb0242ac120002 count error
Traceback (most recent call last):
  File "/fate/fate_flow/utils/session_utils.py", line 96, in _wrapper
    raise Exception("session {} count error".format(session.get_session_id()))
Exception: session session_used_by_fate_flow_server_c3a0f89e19c111ebb5cb0242ac120002 count error
[ERROR] [2020-10-29 08:35:56,668] [6:140637848127232] - session_utils.py[line:100]: session session_used_by_fate_flow_server_c3a31b0619c111ebb5cb0242ac120002 count error
Traceback (most recent call last):
  File "/fate/fate_flow/utils/session_utils.py", line 96, in _wrapper
    raise Exception("session {} count error".format(session.get_session_id()))
Exception: session session_used_by_fate_flow_server_c3a31b0619c111ebb5cb0242ac120002 count error
[ERROR] [2020-10-29 08:35:56,679] [6:140637848127232] - session_utils.py[line:109]: init new session failed.
[ERROR] [2020-10-29 08:37:07,882] [6:140637848127232] - session_utils.py[line:100]: session session_used_by_fate_flow_server_c3a53d0a19c111ebb5cb0242ac120002 count error
Traceback (most recent call last):
  File "/fate/fate_flow/utils/session_utils.py", line 96, in _wrapper
    raise Exception("session {} count error".format(session.get_session_id()))
Exception: session session_used_by_fate_flow_server_c3a53d0a19c111ebb5cb0242ac120002 count error
[ERROR] [2020-10-29 08:37:07,899] [6:140637848127232] - session_utils.py[line:100]: session session_used_by_fate_flow_server_ee17b6d019c111eba8910242ac120002 count error
Traceback (most recent call last):
  File "/fate/fate_flow/utils/session_utils.py", line 96, in _wrapper
    raise Exception("session {} count error".format(session.get_session_id()))
Exception: session session_used_by_fate_flow_server_ee17b6d019c111eba8910242ac120002 count error
[ERROR] [2020-10-29 08:37:07,913] [6:140637848127232] - session_utils.py[line:100]: session session_used_by_fate_flow_server_ee1a53e019c111eba8910242ac120002 count error
Traceback (most recent call last):
  File "/fate/fate_flow/utils/session_utils.py", line 96, in _wrapper
    raise Exception("session {} count error".format(session.get_session_id()))
Exception: session session_used_by_fate_flow_server_ee1a53e019c111eba8910242ac120002 count error
[ERROR] [2020-10-29 08:37:07,926] [6:140637848127232] - session_utils.py[line:109]: init new session failed.
