[ERROR] [2020-10-29 08:12:06,091] [2528:140639642666816] - task_executor.py[line:144]: Count of data_instance is 0, table_name: homo_breast_test, namespace: 202010290812019279649_dataio_1_host_10000
Traceback (most recent call last):
  File "/fate/fate_flow/driver/task_executor.py", line 135, in run_task
    run_object.run(component_parameters, task_run_args)
  File "/fate/federatedml/model_base.py", line 88, in run
    this_data_output = func(*real_param)
  File "/fate/federatedml/util/data_io.py", line 874, in transform
    return self.reader.read_data(data_inst, "transform")
  File "/fate/federatedml/util/data_io.py", line 143, in read_data
    abnormal_detection.empty_table_detection(input_data)
  File "/fate/federatedml/util/abnormal_detection.py", line 28, in empty_table_detection
    table_name, namespace
ValueError: Count of data_instance is 0, table_name: homo_breast_test, namespace: 202010290812019279649_dataio_1_host_10000
